Workbook

Sheet Assumptions and Drivers
B1: ASIAN PAINTS — FORECAST ASSUMPTIONS & DRIVERS
B2: REVENUE DRIVERS | C2: FY27 | D2: FY28 | E2: FY29 | F2: FY30 | G2: FY31 | H2: Rationale
B3: Revenue Growth | C3: 0.095 | D3: 0.095 | E3: 0.09 | F3: 0.085 | G3: 0.08
B4: Other Income | C4: 0.015 | D4: 0.015 | E4: 0.015 | F4: 0.015 | G4: 0.015
B6: COST ASSUMPTIONS | C6: FY27 | D6: FY28 | E6: FY29 | F6: FY30 | G6: FY31
B7: Gross Margin | C7: 0.43 | D7: 0.432 | E7: 0.433 | F7: 0.435 | G7: 0.435
B8: Employee Cost Growth | C8: 0.075 | D8: 0.075 | E8: 0.073 | F8: 0.07 | G8: 0.07
B9: Other Expenses (% Revenue) | C9: 0.17 | D9: 0.17 | E9: 0.17 | F9: 0.17 | G9: 0.17
B10: EBIT Margin | C10: 0.174 | D10: 0.175 | E10: 0.176 | F10: 0.18 | G10: 0.179
B11: EBITDA Margin | C11: 0.204 | D11: 0.204 | E11: 0.206 | F11: 0.21 | G11: 0.209
B12: PAT Margin | C12: 0.128 | D12: 0.129 | E12: 0.13 | F12: 0.133 | G12: 0.133
B13: Depreciation (% Revenue) | C13: 0.03 | D13: 0.03 | E13: 0.03 | F13: 0.03 | G13: 0.03
B14: Finance cost (% Revenue) | C14: 0.005 | D14: 0.005 | E14: 0.005 | F14: 0.005 | G14: 0.005
B15: Share of Profit(in cr) | C15: 20 | D15: 20 | E15: 20 | F15: 20 | G15: 20
B16: Exceptional items | C16: 0 | D16: 0 | E16: 0 | F16: 0 | G16: 0
B17: Effective Tax Rate | C17: 0.26 | D17: 0.26 | E17: 0.26 | F17: 0.26 | G17: 0.26
B18: OCI | C18: 0 | D18: 0 | E18: 0 | F18: 0 | G18: 0
B19: Dividend Payout Ratio (proxy, from Historical CFS) | C19: =ABS('Historical data'!F123/'Historical data'!F25) -> 0.72053319 | D19: =C19 -> 0.72053319 | E19: =D19 -> 0.72053319 | F19: =E19 -> 0.72053319 | G19: =F19 -> 0.72053319 | H19: Forecast payout ratio currently equals the historical consolidated cash-dividend proxy (~72.1%). This differs from the company's stated 60% payout policy based on standalone PAT; choose one basis consistently.
B21: WORKING CAPITAL | C21: FY27 | D21: FY28 | E21: FY29 | F21: FY30 | G21: FY31 | H21: Rationale
B22: Inventory Days | C22: 105 | D22: 105 | E22: 105 | F22: 105 | G22: 105
B23: Receivable Days | C23: 46 | D23: 46 | E23: 46 | F23: 46 | G23: 46
B24: Payable Days | C24: 71 | D24: 71 | E24: 71 | F24: 71 | G24: 71
B26: CAPITAL STRUCTURE | C26: FY27 | D26: FY28 | E26: FY29 | F26: FY30 | G26: FY31 | H26: Rationale
B27: Capex (% Revenue) | C27: 0.05 | D27: 0.05 | E27: 0.05 | F27: 0.05 | G27: 0.05 | H27: PPE capex assumption. Note that total D&A includes PPE, ROU depreciation and amortization; a fully detailed model would split these.
B28: Capex | C28: ='Financial Model'!D5*5% -> 1948.1988 | D28: ='Financial Model'!E5*5% -> 2133.2777 | E28: ='Financial Model'!F5*5% -> 2325.2727 | F28: ='Financial Model'!G5*5% -> 2522.9209 | G28: ='Financial Model'!H5*5% -> 2724.7545
B29: Depreciation & Amortization (% Revenue) | C29: =C13 -> 0.03 | D29: =D13 -> 0.03 | E29: =E13 -> 0.03 | F29: =F13 -> 0.03 | G29: =G13 -> 0.03 | H29: Linked to the operating-model depreciation assumption.
B30: WACC | C30: ='Valuation Output'!C13 -> 0.0996225 | H30: Linked to Valuation Output; calculated from cost of equity, debt cost and capital structure.
B31: Terminal Growth | C31: ='Valuation Output'!F6 -> 0.05 | H31: Linked to Valuation Output; Gordon Growth terminal assumption.
B32: Risk-free Rate | C32: ='Valuation Output'!C6 -> 0.066 | H32: Linked to Valuation Output; Indian government bond yield proxy.
B33: ERP | C33: ='Valuation Output'!C7 -> 0.055 | H33: Linked to Valuation Output; equity risk premium judgment.
B34: Beta | C34: ='Valuation Output'!C8 -> 0.65 | H34: Linked to Valuation Output; levered beta judgment.
B36: MODEL COLOR CONVENTION
B37: Blue font / pale yellow fill | C37: Editable operating assumptions | E37: Green font | F37: Links to other workbook tabs
B38: Black font | C38: Calculated formulas | E38: Red parentheses | F38: Negative values

Sheet Historical data
B2: Asian Paints Limited
B3: Historical Consolidated Income Statement (Fully Dynamic Formulas)
B5: HISTORICAL INCOME STATEMENT | C5: Historical Balance Sheet
B6: Income Statement (₹ Cr) | C6: FY23A | D6: FY24A | E6: FY25A | F6: FY26A
B7: REVENUE FROM OPERATIONS | C7: 34488.59 | D7: 35494.73 | E7: 33905.62 | F7: 35583.54
B8: Other Income | C8: 386.48 | D8: 687.96 | E8: 572.61 | F8: 723.8
B9: TOTAL INCOME (I) | C9: =SUM(C7:C8) -> 34875.07 | D9: =SUM(D7:D8) -> 36182.69 | E9: =SUM(E7:E8) -> 34478.23 | F9: =SUM(F7:F8) -> 36307.34
B11: OPERATING EXPENSES
B12: Cost of Goods Sold | C12: 21156.5 | D12: 20090.21 | E12: 19515.78 | F12: 20001.78
B13: Employee Benefits Expense | C13: 2028.07 | D13: 2326.18 | E13: 2597.23 | F13: 2799.59
B14: Other Expenses | C14: 5044.18 | D14: 5493.36 | E14: 5786.4 | F14: 6086.25
B15: TOTAL OPERATING EXPENSES (II) | C15: =SUM(C12:C14) -> 28228.75 | D15: =SUM(D12:D14) -> 27909.75 | E15: =SUM(E12:E14) -> 27899.41 | F15: =SUM(F12:F14) -> 28887.62
B17: EBITDA | C17: =C9-C15 -> 6646.32 | D17: =D9-D15 -> 8272.94 | E17: =E9-E15 -> 6578.82 | F17: =F9-F15 -> 7419.72
B18: Depreciation & Amortization | C18: 858.02 | D18: 853 | E18: 1026.34 | F18: 1228.85
B19: EBIT(Operating Profit) | C19: =C17-C18 -> 5788.3 | D19: =D17-D18 -> 7419.94 | E19: =E17-E18 -> 5552.48 | F19: =F17-F18 -> 6190.87
B20: Finance Cost | C20: 144.45 | D20: 205.17 | E20: 227.02 | F20: 195.41
B21: Share of Profit in Associates | C21: 93.85 | D21: 133 | E21: 140.71 | F21: 165.59
B22: Exceptional Items | C22: 48.87 | D22: 0 | E22: 363.1 | F22: 157.61
B23: PROFIT BEFORE TAX (PBT) | C23: =C19-C20+C21-C22 -> 5688.83 | D23: =D19-D20+D21-D22 -> 7347.77 | E23: =E19-E20+E21-E22 -> 5103.07 | F23: =F19-F20+F21-F22 -> 6003.44
B24: Total Tax Expense | C24: 1493.5 | D24: 1790.08 | E24: 1393.36 | F24: 1608.75
B25: PROFIT AFTER TAX (PAT) | C25: =C23-C24 -> 4195.33 | D25: =D23-D24 -> 5557.69 | E25: =E23-E24 -> 3709.71 | F25: =F23-F24 -> 4394.69
B26: Other Comprehensive Income (OCI) | C26: 13.04 | D26: 31.96 | E26: 114.56 | F26: -27.36
B27: Total Comprehensive Income | C27: =SUM(C25:C26) -> 4208.37 | D27: =SUM(D25:D26) -> 5589.65 | E27: =SUM(E25:E26) -> 3824.27 | F27: =SUM(F25:F26) -> 4367.33
B31: HISTORICAL BALANCE SHEET | C31: Historical Balance Sheet
B32: Balance Sheet(₹ Cr) | C32: FY23A | D32: FY24A | E32: FY25A | F32: FY26A
B33: ASSETS
B34: Non-Current Assets
B35: Property, Plant and Equipment | C35: 4145.65 | D35: 4446.2 | E35: 6787.62 | F35: 7146.23
B36: Right-of-use Assets | C36: 1208.92 | D36: 1856.27 | E36: 1843.72 | F36: 2018.77
B37: Capital work-in-progress | C37: 1019.59 | D37: 2698.37 | E37: 1254.49 | F37: 1848.67
B38: Intangible Assets & Goodwill | C38: 415.89 | D38: 844.15 | E38: 588.76 | F38: 475.28
B39: Non-Current Investments | C39: 1564.71 | D39: 1384.51 | E39: 1479.79 | F39: 775.91
B40: Other Non-Current Investments | C40: 908.08 | D40: 1157.53 | E40: 1425.31 | F40: 2084.99
B42: Total Non-Current Assets | C42: =SUM(C35:C40) -> 9262.84 | D42: =SUM(D35:D40) -> 12387.03 | E42: =SUM(E35:E40) -> 13379.69 | F42: =SUM(F35:F40) -> 14349.85
B44: Current Assets
B45: Inventories | C45: 6210.64 | D45: 5923.41 | E45: 6719.27 | F45: 5743.69
B46: Trade receivables | C46: 4636.94 | D46: 4889.05 | E46: 4313.65 | F46: 4461.8
B47: Cash & Cash Equivalents(other bal) | C47: 843.82 | D47: 1084.01 | E47: 781.98 | F47: 1073.68
B48: Investments | C48: 2697 | D48: 3203.41 | E48: 3244.96 | F48: 6285.83
B49: Other Current Assets | C49: 2146.76 | D49: 2437.18 | E49: 1931.82 | F49: 2619.64
...

Sheet Financial Model
D2: Forecast Income Statement
B3: Income Statement (₹ Cr) | C3: FY26A | D3: FY27E | E3: FY28E | F3: FY29E | G3: FY30E | H3: FY31E
B5: REVENUE | C5: ='Historical data'!F7 -> 35583.54 | D5: =C5*(1+'Assumptions and Drivers'!C3) -> 38963.976 | E5: =D5*(1+'Assumptions and Drivers'!D3) -> 42665.554 | F5: =E5*(1+'Assumptions and Drivers'!E3) -> 46505.454 | G5: =F5*(1+'Assumptions and Drivers'!F3) -> 50458.417 | H5: =G5*(1+'Assumptions and Drivers'!G3) -> 54495.091
B6: Other Income | C6: ='Historical data'!F8 -> 723.8 | D6: =C6*(1+'Assumptions and Drivers'!C4) -> 734.657 | E6: =D6*(1+'Assumptions and Drivers'!D4) -> 745.67685 | F6: =E6*(1+'Assumptions and Drivers'!E4) -> 756.86201 | G6: =F6*(1+'Assumptions and Drivers'!F4) -> 768.21494 | H6: =G6*(1+'Assumptions and Drivers'!G4) -> 779.73816
B7: TOTAL INCOME (I) | C7: =SUM(C5:C6) -> 36307.34 | D7: =SUM(D5:D6) -> 39698.633 | E7: =SUM(E5:E6) -> 43411.231 | F7: =SUM(F5:F6) -> 47262.316 | G7: =SUM(G5:G6) -> 51226.632 | H7: =SUM(H5:H6) -> 55274.829
B9: OPERATING EXPENSES
B10: Cost of Goods Sold | C10: ='Historical data'!F12 -> 20001.78 | D10: =D5*(1-'Assumptions and Drivers'!C7) -> 22209.466 | E10: =E5*(1-'Assumptions and Drivers'!D7) -> 24234.035 | F10: =F5*(1-'Assumptions and Drivers'!E7) -> 26368.592 | G10: =G5*(1-'Assumptions and Drivers'!F7) -> 28509.006 | H10: =H5*(1-'Assumptions and Drivers'!G7) -> 30789.726
B11: Employee Benefits Expense | C11: ='Historical data'!F13 -> 2799.59 | D11: =D5*'Assumptions and Drivers'!C8 -> 2922.2982 | E11: =E5*'Assumptions and Drivers'!D8 -> 3199.9166 | F11: =F5*'Assumptions and Drivers'!E8 -> 3394.8981 | G11: =G5*'Assumptions and Drivers'!F8 -> 3532.0892 | H11: =H5*'Assumptions and Drivers'!G8 -> 3814.6564
B12: Other Expenses | C12: ='Historical data'!F14 -> 6086.25 | D12: =D5*'Assumptions and Drivers'!C9 -> 6623.876 | E12: =E5*'Assumptions and Drivers'!D9 -> 7253.1442 | F12: =F5*'Assumptions and Drivers'!E9 -> 7905.9272 | G12: =G5*'Assumptions and Drivers'!F9 -> 8577.931 | H12: =H5*'Assumptions and Drivers'!G9 -> 9264.1655
B13: TOTAL OPERATING EXPENSES (II) | C13: =SUM(C10:C12) -> 28887.62 | D13: =SUM(D10:D12) -> 31755.641 | E13: =SUM(E10:E12) -> 34687.095 | F13: =SUM(F10:F12) -> 37669.418 | G13: =SUM(G10:G12) -> 40619.026 | H13: =SUM(H10:H12) -> 43868.548
B15: EBITDA | C15: =C7-C13 -> 7419.72 | D15: =D7-D13 -> 7942.9926 | E15: =E7-E13 -> 8724.1355 | F15: =F7-F13 -> 9592.8983 | G15: =G7-G13 -> 10607.606 | H15: =H7-H13 -> 11406.281
B16: Depreciation & Amortization | C16: ='Historical data'!F18 -> 1228.85 | D16: =D5*'Assumptions and Drivers'!C13 -> 1168.9193 | E16: =E5*'Assumptions and Drivers'!D13 -> 1279.9666 | F16: =F5*'Assumptions and Drivers'!E13 -> 1395.1636 | G16: =G5*'Assumptions and Drivers'!F13 -> 1513.7525 | H16: =H5*'Assumptions and Drivers'!G13 -> 1634.8527
B18: EBIT(Operating Profit) | C18: =C15-C16 -> 6190.87 | D18: =D15-D16 -> 6774.0733 | E18: =E15-E16 -> 7444.1688 | F18: =F15-F16 -> 8197.7346 | G18: =G15-G16 -> 9093.8538 | H18: =H15-H16 -> 9771.4282
B19: Finance Cost | C19: ='Historical data'!F20 -> 195.41 | D19: =D5*'Assumptions and Drivers'!C14 -> 194.81988 | E19: =E5*'Assumptions and Drivers'!D14 -> 213.32777 | F19: =F5*'Assumptions and Drivers'!E14 -> 232.52727 | G19: =G5*'Assumptions and Drivers'!F14 -> 252.29209 | H19: =H5*'Assumptions and Drivers'!G14 -> 272.47545
B20: Share of Profit in Associates | C20: ='Historical data'!F21 -> 165.59 | D20: =C20+'Assumptions and Drivers'!C15 -> 185.59 | E20: =D20+'Assumptions and Drivers'!D15 -> 205.59 | F20: =E20+'Assumptions and Drivers'!E15 -> 225.59 | G20: =F20+'Assumptions and Drivers'!F15 -> 245.59 | H20: =G20+'Assumptions and Drivers'!G15 -> 265.59
B21: Exceptional Items | C21: ='Historical data'!F22 -> 157.61 | D21: ='Assumptions and Drivers'!C16 -> 0 | E21: ='Assumptions and Drivers'!D16 -> 0 | F21: ='Assumptions and Drivers'!E16 -> 0 | G21: ='Assumptions and Drivers'!F16 -> 0 | H21: ='Assumptions and Drivers'!G16 -> 0
B23: PROFIT BEFORE TAX (PBT) | C23: ='Historical data'!F23 -> 6003.44 | D23: =D18-D19+D20+D21 -> 6764.8434 | E23: =E18-E19+E20+E21 -> 7436.4311 | F23: =F18-F19+F20+F21 -> 8190.7974 | G23: =G18-G19+G20+G21 -> 9087.1517 | H23: =H18-H19+H20+H21 -> 9764.5427
B24: Total Tax Expense | C24: ='Historical data'!F24 -> 1608.75 | D24: =D23*'Assumptions and Drivers'!C17 -> 1758.8593 | E24: =E23*'Assumptions and Drivers'!D17 -> 1933.4721 | F24: =F23*'Assumptions and Drivers'!E17 -> 2129.6073 | G24: =G23*'Assumptions and Drivers'!F17 -> 2362.6595 | H24: =H23*'Assumptions and Drivers'!G17 -> 2538.7811
B26: PROFIT AFTER TAX (PAT) | C26: =C23-C24 -> 4394.69 | D26: =D23-D24 -> 5005.9841 | E26: =E23-E24 -> 5502.959 | F26: =F23-F24 -> 6061.19 | G26: =G23-G24 -> 6724.4923 | H26: =H23-H24 -> 7225.7616
B27: Other Comprehensive Income (OCI) | C27: ='Historical data'!F26 -> -27.36 | D27: ='Assumptions and Drivers'!C18 -> 0 | E27: ='Assumptions and Drivers'!D18 -> 0 | F27: ='Assumptions and Drivers'!E18 -> 0 | G27: ='Assumptions and Drivers'!F18 -> 0 | H27: ='Assumptions and Drivers'!G18 -> 0
B28: Total Comprehensive Income | C28: =C26+C27 -> 4367.33 | D28: =D26+D27 -> 5005.9841 | E28: =E26+E27 -> 5502.959 | F28: =F26+F27 -> 6061.19 | G28: =G26+G27 -> 6724.4923 | H28: =H26+H27 -> 7225.7616
B31: Balance Sheet (₹ Cr) | C31: FY26A | D31: FY27E | E31: FY28E | F31: FY29E | G31: FY30E | H31: FY31E
B33: ASSETS
B34: Non-Current Assets
B35: Property, Plant and Equipment | C35: ='Historical data'!F35 -> 7146.23 | D35: =C35+'Assumptions and Drivers'!C28-D16 -> 7925.5095 | E35: =D35+'Assumptions and Drivers'!D28-E16 -> 8778.8206 | F35: =E35+'Assumptions and Drivers'!E28-F16 -> 9708.9297 | G35: =F35+'Assumptions and Drivers'!F28-G16 -> 10718.098 | H35: =G35+'Assumptions and Drivers'!G28-H16 -> 11808
B36: Right-of-use Assets | C36: ='Historical data'!F36 -> 2018.77 | D36: =C36*1.02 -> 2059.1454 | E36: =D36*1.02 -> 2100.3283 | F36: =E36*1.02 -> 2142.3349 | G36: =F36*1.02 -> 2185.1816 | H36: =G36*1.02 -> 2228.8852
B37: Capital work-in-progress | C37: ='Historical data'!F37 -> 1848.67 | D37: =C37 -> 1848.67 | E37: =D37 -> 1848.67 | F37: =E37 -> 1848.67 | G37: =F37 -> 1848.67 | H37: =G37 -> 1848.67
B38: Intangible Assets & Goodwill | C38: ='Historical data'!F38 -> 475.28 | D38: =C38*(1+1%) -> 480.0328 | E38: =D38*(1+1%) -> 484.83313 | F38: =E38*(1+1%) -> 489.68146 | G38: =F38*(1+1%) -> 494.57827 | H38: =G38*(1+1%) -> 499.52406
B39: Non-Current Investments | C39: ='Historical data'!F39 -> 775.91 | D39: =C39 -> 775.91 | E39: =D39 -> 775.91 | F39: =E39 -> 775.91 | G39: =F39 -> 775.91 | H39: =G39 -> 775.91
B40: Other Non-Current Investments | C40: ='Historical data'!F40 -> 2084.99 | D40: =C40 -> 2084.99 | E40: =D40 -> 2084.99 | F40: =E40 -> 2084.99 | G40: =F40 -> 2084.99 | H40: =G40 -> 2084.99
B42: Total Non-Current Assets | C42: =SUM(C35:C40) -> 14349.85 | D42: =SUM(D35:D40) -> 15174.258 | E42: =SUM(E35:E40) -> 16073.552 | F42: =SUM(F35:F40) -> 17050.516 | G42: =SUM(G35:G40) -> 18107.428 | H42: =SUM(H35:H40) -> 19245.979
B44: Current Assets
B45: Inventories | C45: ='Historical data'!F45 -> 5743.69 | D45: ='Assumptions and Drivers'!C22/365*D10 -> 6389.0246 | E45: ='Assumptions and Drivers'!D22/365*E10 -> 6971.4346 | F45: ='Assumptions and Drivers'!E22/365*F10 -> 7585.4855 | G45: ='Assumptions and Drivers'!F22/365*G10 -> 8201.2209 | H45: ='Assumptions and Drivers'!G22/365*H10 -> 8857.3185
B46: Trade receivables | C46: ='Historical data'!F46 -> 4461.8 | D46: ='Assumptions and Drivers'!C23/365*D5 -> 4910.5285 | E46: ='Assumptions and Drivers'!D23/365*E5 -> 5377.0287 | F46: ='Assumptions and Drivers'!E23/365*F5 -> 5860.9613 | G46: ='Assumptions and Drivers'!F23/365*G5 -> 6359.143 | H46: ='Assumptions and Drivers'!G23/365*H5 -> 6867.8745
B47: Cash & Cash Equivalents(other bal) | C47: ='Historical data'!F47 -> 1073.68 | D47: =D112 -> 1393.3923 | E47: =E112 -> 1800.0351 | F47: =F112 -> 2279.1531 | G47: =G112 -> 2869.9134 | H47: =H112 -> 3503.0305
B48: Investments | C48: ='Historical data'!F48 -> 6285.83 | D48: =C48 -> 6285.83 | E48: =D48 -> 6285.83 | F48: =E48 -> 6285.83 | G48: =F48 -> 6285.83 | H48: =G48 -> 6285.83
B49: Other Current Assets | C49: ='Historical data'!F49 -> 2619.64 | D49: =C49 -> 2619.64 | E49: =D49 -> 2619.64 | F49: =E49 -> 2619.64 | G49: =F49 -> 2619.64 | H49: =G49 -> 2619.64
B51: Total Current Assets | C51: =SUM(C45:C49) -> 20184.64 | D51: =SUM(D45:D49) -> 21598.415 | E51: =SUM(E45:E49) -> 23053.968 | F51: =SUM(F45:F49) -> 24631.07 | G51: =SUM(G45:G49) -> 26335.747 | H51: =SUM(H45:H49) -> 28133.694
B53: TOTAL ASSETS | C53: =C42+C51 -> 34534.49 | D53: =D42+D51 -> 36772.673 | E53: =E42+E51 -> 39127.521 | F53: =F42+F51 -> 41681.586 | G53: =G42+G51 -> 44443.175 | H53: =H42+H51 -> 47379.673
B55: EQUITY AND LIABILITIES
...

Sheet Valuation Output
B2: ASIAN PAINTS — DCF VALUATION
B3: Valuation date | C3: 31-Mar-2026 | D3: Method | E3: Unlevered FCF / Gordon Growth | F3: Units | G3: ₹ Cr | H3: Consolidated
B5: WACC & TERMINAL VALUE ASSUMPTIONS
B6: Risk-free rate | C6: 0.066 | E6: Terminal growth | F6: 0.05
B7: Equity risk premium | C7: 0.055 | E7: Shares outstanding (Cr) | F7: 95.92
B8: Levered beta | C8: 0.65 | E8: Selected scenario | F8: Base
B9: Cost of equity | C9: =C6+C7*C8 -> 0.10175 | E9: Valuation convention | F9: Year-end discounting
B10: Pre-tax cost of debt | C10: 0.08
B11: Target equity weight | C11: 0.95
B12: Target debt weight | C12: 0.05
B13: WACC | C13: =C9*C11+C10*(1-'Assumptions and Drivers'!C17)*C12 -> 0.0996225
B15: UNLEVERED FREE CASH FLOW
B16: ₹ Cr unless stated | C16: FY26A | D16: FY27E | E16: FY28E | F16: FY29E | G16: FY30E | H16: FY31E
B17: Revenue | C17: ='Financial Model'!C5 -> 35583.54 | D17: ='Financial Model'!D5 -> 38963.976 | E17: ='Financial Model'!E5 -> 42665.554 | F17: ='Financial Model'!F5 -> 46505.454 | G17: ='Financial Model'!G5 -> 50458.417 | H17: ='Financial Model'!H5 -> 54495.091
B18: EBIT | C18: ='Financial Model'!C18 -> 6190.87 | D18: ='Financial Model'!D18 -> 6774.0733 | E18: ='Financial Model'!E18 -> 7444.1688 | F18: ='Financial Model'!F18 -> 8197.7346 | G18: ='Financial Model'!G18 -> 9093.8538 | H18: ='Financial Model'!H18 -> 9771.4282
B19: Tax rate | C19: ='Financial Model'!C24/'Financial Model'!C23 -> 0.26797136 | D19: ='Assumptions and Drivers'!C17 -> 0.26 | E19: ='Assumptions and Drivers'!D17 -> 0.26 | F19: ='Assumptions and Drivers'!E17 -> 0.26 | G19: ='Assumptions and Drivers'!F17 -> 0.26 | H19: ='Assumptions and Drivers'!G17 -> 0.26
B20: NOPAT | C20: =C18*(1-C19) -> 4531.8941 | D20: =D18*(1-D19) -> 5012.8143 | E20: =E18*(1-E19) -> 5508.6849 | F20: =F18*(1-F19) -> 6066.3236 | G20: =G18*(1-G19) -> 6729.4518 | H20: =H18*(1-H19) -> 7230.8568
B21: D&A | C21: ='Financial Model'!C16 -> 1228.85 | D21: ='Financial Model'!D16 -> 1168.9193 | E21: ='Financial Model'!E16 -> 1279.9666 | F21: ='Financial Model'!F16 -> 1395.1636 | G21: ='Financial Model'!G16 -> 1513.7525 | H21: ='Financial Model'!H16 -> 1634.8527
B22: Capital expenditure | C22: =-'Historical data'!F104-'Historical data'!F106 -> 1897.42 | D22: =-'Financial Model'!D98-'Financial Model'!D99-'Financial Model'!D100 -> 1993.327 | E22: =-'Financial Model'!E98-'Financial Model'!E99-'Financial Model'!E100 -> 2179.2609 | F22: =-'Financial Model'!F98-'Financial Model'!F99-'Financial Model'!F100 -> 2372.1276 | G22: =-'Financial Model'!G98-'Financial Model'!G99-'Financial Model'!G100 -> 2570.6644 | H22: =-'Financial Model'!H98-'Financial Model'!H99-'Financial Model'!H100 -> 2773.404
B23: Operating NWC | C23: ='Supporting Schedules'!C18 -> 5242.93 | D23: ='Supporting Schedules'!D18 -> 5526.5153 | E23: ='Supporting Schedules'!E18 -> 5794.7198 | F23: ='Supporting Schedules'!F18 -> 6076.145 | G23: ='Supporting Schedules'!G18 -> 6360.5475 | H23: ='Supporting Schedules'!H18 -> 6659.8201
B24: Change in NWC | C24: ='Supporting Schedules'!C19 -> 0 | D24: ='Supporting Schedules'!D19 -> 283.58534 | E24: ='Supporting Schedules'!E19 -> 268.20451 | F24: ='Supporting Schedules'!F19 -> 281.42517 | G24: ='Supporting Schedules'!G19 -> 284.40245 | H24: ='Supporting Schedules'!H19 -> 299.2726
B25: Unlevered FCF | C25: =C20+C21-C22-C24 -> 3863.3241 | D25: =D20+D21-D22-D24 -> 3904.8212 | E25: =E20+E21-E22-E24 -> 4341.1861 | F25: =F20+F21-F22-F24 -> 4807.9345 | G25: =G20+G21-G22-G24 -> 5388.1375 | H25: =H20+H21-H22-H24 -> 5793.033
B26: Discount factor | C26: =1 -> 1 | D26: =1/(1+$C$13)^1 -> 0.909403 | E26: =1/(1+$C$13)^2 -> 0.82701382 | F26: =1/(1+$C$13)^3 -> 0.75208884 | G26: =1/(1+$C$13)^4 -> 0.68395185 | H26: =1/(1+$C$13)^5 -> 0.62198787
B27: PV of UFCF | C27: =C25 -> 3863.3241 | D27: =D25*D26 -> 3551.0561 | E27: =E25*E26 -> 3590.2209 | F27: =F25*F26 -> 3615.9939 | G27: =G25*G26 -> 3685.2266 | H27: =H25*H26 -> 3603.1962
B29: ENTERPRISE TO EQUITY VALUE BRIDGE
B30: PV of forecast UFCF | C30: =SUM(D27:H27) -> 18045.694
B31: Terminal-year UFCF | C31: =H25 -> 5793.033
B32: Terminal value | C32: =C31*(1+$F$6)/($C$13-$F$6) -> 122579.17
B33: PV of terminal value | C33: =C32*H26 -> 76242.754
B34: Enterprise value | C34: =C30+C33 -> 94288.447
B35: Less: Borrowings & leases | C35: ='Supporting Schedules'!C26 -> 3928.93
B36: Add: Cash & current investments | C36: ='Financial Model'!C47+'Financial Model'!C48 -> 7359.51
B37: Net debt / (net cash) | C37: =C35-C36 -> -3430.58
B38: Less: Non-controlling interests | C38: ='Financial Model'!C58 -> 643.39
B39: Equity value | C39: =C34-C37-C38 -> 97075.637
B40: Shares outstanding (Cr) | C40: =$F$7 -> 95.92
B41: Implied value per share | C41: =C39/C40 -> 1012.0479

Sheet Supporting Schedules
B2: SUPPORTING SCHEDULES
B3: ₹ Cr unless stated | C3: FY26A | D3: FY27E | E3: FY28E | F3: FY29E | G3: FY30E | H3: FY31E
B5: PROPERTY, PLANT & EQUIPMENT
B6: Opening PPE | C6: ='Financial Model'!C35 -> 7146.23 | D6: ='Financial Model'!C35 -> 7146.23 | E6: ='Financial Model'!D35 -> 7925.5095 | F6: ='Financial Model'!E35 -> 8778.8206 | G6: ='Financial Model'!F35 -> 9708.9297 | H6: ='Financial Model'!G35 -> 10718.098
B7: Capital expenditure | C7: =-'Historical data'!F104 -> 1675.69 | D7: ='Assumptions and Drivers'!C28 -> 1948.1988 | E7: ='Assumptions and Drivers'!D28 -> 2133.2777 | F7: ='Assumptions and Drivers'!E28 -> 2325.2727 | G7: ='Assumptions and Drivers'!F28 -> 2522.9209 | H7: ='Assumptions and Drivers'!G28 -> 2724.7545
B8: Depreciation & amortisation allocated to PPE | C8: ='Financial Model'!C16 -> 1228.85 | D8: ='Financial Model'!D16 -> 1168.9193 | E8: ='Financial Model'!E16 -> 1279.9666 | F8: ='Financial Model'!F16 -> 1395.1636 | G8: ='Financial Model'!G16 -> 1513.7525 | H8: ='Financial Model'!H16 -> 1634.8527
B9: Closing PPE | C9: ='Financial Model'!C35 -> 7146.23 | D9: ='Financial Model'!D35 -> 7925.5095 | E9: ='Financial Model'!E35 -> 8778.8206 | F9: ='Financial Model'!F35 -> 9708.9297 | G9: ='Financial Model'!G35 -> 10718.098 | H9: ='Financial Model'!H35 -> 11808
B10: Roll-forward check | C10: =0 -> 0 | D10: =D6+D7-D8-D9 -> 0 | E10: =E6+E7-E8-E9 -> 0 | F10: =F6+F7-F8-F9 -> 0 | G10: =G6+G7-G8-G9 -> 0 | H10: =H6+H7-H8-H9 -> 0
B12: OPERATING WORKING CAPITAL
B13: Inventories | C13: ='Financial Model'!C45 -> 5743.69 | D13: ='Financial Model'!D45 -> 6389.0246 | E13: ='Financial Model'!E45 -> 6971.4346 | F13: ='Financial Model'!F45 -> 7585.4855 | G13: ='Financial Model'!G45 -> 8201.2209 | H13: ='Financial Model'!H45 -> 8857.3185
B14: Trade receivables | C14: ='Financial Model'!C46 -> 4461.8 | D14: ='Financial Model'!D46 -> 4910.5285 | E14: ='Financial Model'!E46 -> 5377.0287 | F14: ='Financial Model'!F46 -> 5860.9613 | G14: ='Financial Model'!G46 -> 6359.143 | H14: ='Financial Model'!H46 -> 6867.8745
B15: Other current assets | C15: ='Financial Model'!C49 -> 2619.64 | D15: ='Financial Model'!D49 -> 2619.64 | E15: ='Financial Model'!E49 -> 2619.64 | F15: ='Financial Model'!F49 -> 2619.64 | G15: ='Financial Model'!G49 -> 2619.64 | H15: ='Financial Model'!H49 -> 2619.64
B16: Less: Trade payables | C16: ='Financial Model'!C71 -> 3863.04 | D16: ='Financial Model'!D71 -> 4320.1976 | E16: ='Financial Model'!E71 -> 4714.0177 | F16: ='Financial Model'!F71 -> 5129.233 | G16: ='Financial Model'!G71 -> 5545.5874 | H16: ='Financial Model'!H71 -> 5989.2344
B17: Less: Other current liabilities | C17: ='Financial Model'!C74 -> 3719.16 | D17: ='Financial Model'!D74 -> 4072.4802 | E17: ='Financial Model'!E74 -> 4459.3658 | F17: ='Financial Model'!F74 -> 4860.7087 | G17: ='Financial Model'!G74 -> 5273.869 | H17: ='Financial Model'!H74 -> 5695.7785
B18: Operating net working capital | C18: =C13+C14+C15-C16-C17 -> 5242.93 | D18: =D13+D14+D15-D16-D17 -> 5526.5153 | E18: =E13+E14+E15-E16-E17 -> 5794.7198 | F18: =F13+F14+F15-F16-F17 -> 6076.145 | G18: =G13+G14+G15-G16-G17 -> 6360.5475 | H18: =H13+H14+H15-H16-H17 -> 6659.8201
B19: Change in NWC | C19: =0 -> 0 | D19: =D18-C18 -> 283.58534 | E19: =E18-D18 -> 268.20451 | F19: =F18-E18 -> 281.42517 | G19: =G18-F18 -> 284.40245 | H19: =H18-G18 -> 299.2726
B21: DEBT & LEASE OBLIGATIONS
B22: Long-term borrowings | C22: ='Financial Model'!C63 -> 1247.17 | D22: ='Financial Model'!D63 -> 1247.17 | E22: ='Financial Model'!E63 -> 1247.17 | F22: ='Financial Model'!F63 -> 1247.17 | G22: ='Financial Model'!G63 -> 1247.17 | H22: ='Financial Model'!H63 -> 1247.17
B23: Short-term borrowings | C23: ='Financial Model'!C70 -> 1046.09 | D23: ='Financial Model'!D70 -> 1046.09 | E23: ='Financial Model'!E70 -> 1046.09 | F23: ='Financial Model'!F70 -> 1046.09 | G23: ='Financial Model'!G70 -> 1046.09 | H23: ='Financial Model'!H70 -> 1046.09
B24: Non-current lease liabilities | C24: ='Financial Model'!C64 -> 1306.94 | D24: ='Financial Model'!D64 -> 1281.3137 | E24: ='Financial Model'!E64 -> 1256.1899 | F24: ='Financial Model'!F64 -> 1231.5588 | G24: ='Financial Model'!G64 -> 1207.4105 | H24: ='Financial Model'!H64 -> 1183.7358
B25: Current lease liabilities | C25: ='Financial Model'!C72 -> 328.73 | D25: ='Financial Model'!D72 -> 322.28431 | E25: ='Financial Model'!E72 -> 315.96501 | F25: ='Financial Model'!F72 -> 309.76962 | G25: ='Financial Model'!G72 -> 303.69571 | H25: ='Financial Model'!H72 -> 297.74089
B26: Total debt & leases | C26: =SUM(C22:C25) -> 3928.93 | D26: =SUM(D22:D25) -> 3896.858 | E26: =SUM(E22:E25) -> 3865.4149 | F26: =SUM(F22:F25) -> 3834.5884 | G26: =SUM(G22:G25) -> 3804.3662 | H26: =SUM(H22:H25) -> 3774.7367
B27: Annual movement | C27: =0 -> 0 | D27: =D26-C26 -> -32.071961 | E27: =E26-D26 -> -31.443099 | F27: =F26-E26 -> -30.826567 | G27: =G26-F26 -> -30.222125 | H27: =H26-G26 -> -29.629534

Sheet Sensitivity & Scenarios
B2: SENSITIVITY & SCENARIO ANALYSIS
B3: Sensitivity is formula-driven from the DCF. Scenarios use explicit UFCF multipliers, WACC and terminal growth assumptions; they do not overwrite the operating model.
B5: DCF VALUE PER SHARE — WACC / TERMINAL GROWTH
C7: WACC / g | D7: 0.04 | E7: 0.045 | F7: 0.05 | G7: 0.055 | H7: 0.06
C8: 0.09 | D8: =(('Valuation Output'!D25/(1+$C8)^1+'Valuation Output'!E25/(1+$C8)^2+'Valuation Output'!F25/(1+$C8)^3+'Valuation Output'!G25/(1+$C8)^4+'Valuation Output'!H25/(1+$C8)^5+('Valuation Output'!H25*(1+D$7)/($C8-D$7))/(1+$C8)^5)-'Valuation Output'!C37-'Valuation Output'!C38)/'Valuation Output'!C40 -> 1038.6968 | E8: =(('Valuation Output'!D25/(1+$C8)^1+'Valuation Output'!E25/(1+$C8)^2+'Valuation Output'!F25/(1+$C8)^3+'Valuation Output'!G25/(1+$C8)^4+'Valuation Output'!H25/(1+$C8)^5+('Valuation Output'!H25*(1+E$7)/($C8-E$7))/(1+$C8)^5)-'Valuation Output'!C37-'Valuation Output'!C38)/'Valuation Output'!C40 -> 1133.7744 | F8: =(('Valuation Output'!D25/(1+$C8)^1+'Valuation Output'!E25/(1+$C8)^2+'Valuation Output'!F25/(1+$C8)^3+'Valuation Output'!G25/(1+$C8)^4+'Valuation Output'!H25/(1+$C8)^5+('Valuation Output'!H25*(1+F$7)/($C8-F$7))/(1+$C8)^5)-'Valuation Output'!C37-'Valuation Output'!C38)/'Valuation Output'!C40 -> 1252.6215 | G8: =(('Valuation Output'!D25/(1+$C8)^1+'Valuation Output'!E25/(1+$C8)^2+'Valuation Output'!F25/(1+$C8)^3+'Valuation Output'!G25/(1+$C8)^4+'Valuation Output'!H25/(1+$C8)^5+('Valuation Output'!H25*(1+G$7)/($C8-G$7))/(1+$C8)^5)-'Valuation Output'!C37-'Valuation Output'!C38)/'Valuation Output'!C40 -> 1405.4248 | H8: =(('Valuation Output'!D25/(1+$C8)^1+'Valuation Output'!E25/(1+$C8)^2+'Valuation Output'!F25/(1+$C8)^3+'Valuation Output'!G25/(1+$C8)^4+'Valuation Output'!H25/(1+$C8)^5+('Valuation Output'!H25*(1+H$7)/($C8-H$7))/(1+$C8)^5)-'Valuation Output'!C37-'Valuation Output'!C38)/'Valuation Output'!C40 -> 1609.1626
C9: 0.095 | D9: =(('Valuation Output'!D25/(1+$C9)^1+'Valuation Output'!E25/(1+$C9)^2+'Valuation Output'!F25/(1+$C9)^3+'Valuation Output'!G25/(1+$C9)^4+'Valuation Output'!H25/(1+$C9)^5+('Valuation Output'!H25*(1+D$7)/($C9-D$7))/(1+$C9)^5)-'Valuation Output'!C37-'Valuation Output'!C38)/'Valuation Output'!C40 -> 945.02738 | E9: =(('Valuation Output'!D25/(1+$C9)^1+'Valuation Output'!E25/(1+$C9)^2+'Valuation Output'!F25/(1+$C9)^3+'Valuation Output'!G25/(1+$C9)^4+'Valuation Output'!H25/(1+$C9)^5+('Valuation Output'!H25*(1+E$7)/($C9-E$7))/(1+$C9)^5)-'Valuation Output'!C37-'Valuation Output'!C38)/'Valuation Output'!C40 -> 1021.407 | F9: =(('Valuation Output'!D25/(1+$C9)^1+'Valuation Output'!E25/(1+$C9)^2+'Valuation Output'!F25/(1+$C9)^3+'Valuation Output'!G25/(1+$C9)^4+'Valuation Output'!H25/(1+$C9)^5+('Valuation Output'!H25*(1+F$7)/($C9-F$7))/(1+$C9)^5)-'Valuation Output'!C37-'Valuation Output'!C38)/'Valuation Output'!C40 -> 1114.7599 | G9: =(('Valuation Output'!D25/(1+$C9)^1+'Valuation Output'!E25/(1+$C9)^2+'Valuation Output'!F25/(1+$C9)^3+'Valuation Output'!G25/(1+$C9)^4+'Valuation Output'!H25/(1+$C9)^5+('Valuation Output'!H25*(1+G$7)/($C9-G$7))/(1+$C9)^5)-'Valuation Output'!C37-'Valuation Output'!C38)/'Valuation Output'!C40 -> 1231.4511 | H9: =(('Valuation Output'!D25/(1+$C9)^1+'Valuation Output'!E25/(1+$C9)^2+'Valuation Output'!F25/(1+$C9)^3+'Valuation Output'!G25/(1+$C9)^4+'Valuation Output'!H25/(1+$C9)^5+('Valuation Output'!H25*(1+H$7)/($C9-H$7))/(1+$C9)^5)-'Valuation Output'!C37-'Valuation Output'!C38)/'Valuation Output'!C40 -> 1381.4825
C10: 0.1 | D10: =(('Valuation Output'!D25/(1+$C10)^1+'Valuation Output'!E25/(1+$C10)^2+'Valuation Output'!F25/(1+$C10)^3+'Valuation Output'!G25/(1+$C10)^4+'Valuation Output'!H25/(1+$C10)^5+('Valuation Output'!H25*(1+D$7)/($C10-D$7))/(1+$C10)^5)-'Valuation Output'!C37-'Valuation Output'!C38)/'Valuation Output'!C40 -> 866.99908 | E10: =(('Valuation Output'!D25/(1+$C10)^1+'Valuation Output'!E25/(1+$C10)^2+'Valuation Output'!F25/(1+$C10)^3+'Valuation Output'!G25/(1+$C10)^4+'Valuation Output'!H25/(1+$C10)^5+('Valuation Output'!H25*(1+E$7)/($C10-E$7))/(1+$C10)^5)-'Valuation Output'!C37-'Valuation Output'!C38)/'Valuation Output'!C40 -> 929.49939 | F10: =(('Valuation Output'!D25/(1+$C10)^1+'Valuation Output'!E25/(1+$C10)^2+'Valuation Output'!F25/(1+$C10)^3+'Valuation Output'!G25/(1+$C10)^4+'Valuation Output'!H25/(1+$C10)^5+('Valuation Output'!H25*(1+F$7)/($C10-F$7))/(1+$C10)^5)-'Valuation Output'!C37-'Valuation Output'!C38)/'Valuation Output'!C40 -> 1004.4998 | G10: =(('Valuation Output'!D25/(1+$C10)^1+'Valuation Output'!E25/(1+$C10)^2+'Valuation Output'!F25/(1+$C10)^3+'Valuation Output'!G25/(1+$C10)^4+'Valuation Output'!H25/(1+$C10)^5+('Valuation Output'!H25*(1+G$7)/($C10-G$7))/(1+$C10)^5)-'Valuation Output'!C37-'Valuation Output'!C38)/'Valuation Output'!C40 -> 1096.1669 | H10: =(('Valuation Output'!D25/(1+$C10)^1+'Valuation Output'!E25/(1+$C10)^2+'Valuation Output'!F25/(1+$C10)^3+'Valuation Output'!G25/(1+$C10)^4+'Valuation Output'!H25/(1+$C10)^5+('Valuation Output'!H25*(1+H$7)/($C10-H$7))/(1+$C10)^5)-'Valuation Output'!C37-'Valuation Output'!C38)/'Valuation Output'!C40 -> 1210.7508
C11: 0.105 | D11: =(('Valuation Output'!D25/(1+$C11)^1+'Valuation Output'!E25/(1+$C11)^2+'Valuation Output'!F25/(1+$C11)^3+'Valuation Output'!G25/(1+$C11)^4+'Valuation Output'!H25/(1+$C11)^5+('Valuation Output'!H25*(1+D$7)/($C11-D$7))/(1+$C11)^5)-'Valuation Output'!C37-'Valuation Output'!C38)/'Valuation Output'!C40 -> 801.00181 | E11: =(('Valuation Output'!D25/(1+$C11)^1+'Valuation Output'!E25/(1+$C11)^2+'Valuation Output'!F25/(1+$C11)^3+'Valuation Output'!G25/(1+$C11)^4+'Valuation Output'!H25/(1+$C11)^5+('Valuation Output'!H25*(1+E$7)/($C11-E$7))/(1+$C11)^5)-'Valuation Output'!C37-'Valuation Output'!C38)/'Valuation Output'!C40 -> 852.93597 | F11: =(('Valuation Output'!D25/(1+$C11)^1+'Valuation Output'!E25/(1+$C11)^2+'Valuation Output'!F25/(1+$C11)^3+'Valuation Output'!G25/(1+$C11)^4+'Valuation Output'!H25/(1+$C11)^5+('Valuation Output'!H25*(1+F$7)/($C11-F$7))/(1+$C11)^5)-'Valuation Output'!C37-'Valuation Output'!C38)/'Valuation Output'!C40 -> 914.31271 | G11: =(('Valuation Output'!D25/(1+$C11)^1+'Valuation Output'!E25/(1+$C11)^2+'Valuation Output'!F25/(1+$C11)^3+'Valuation Output'!G25/(1+$C11)^4+'Valuation Output'!H25/(1+$C11)^5+('Valuation Output'!H25*(1+G$7)/($C11-G$7))/(1+$C11)^5)-'Valuation Output'!C37-'Valuation Output'!C38)/'Valuation Output'!C40 -> 987.96479 | H11: =(('Valuation Output'!D25/(1+$C11)^1+'Valuation Output'!E25/(1+$C11)^2+'Valuation Output'!F25/(1+$C11)^3+'Valuation Output'!G25/(1+$C11)^4+'Valuation Output'!H25/(1+$C11)^5+('Valuation Output'!H25*(1+H$7)/($C11-H$7))/(1+$C11)^5)-'Valuation Output'!C37-'Valuation Output'!C38)/'Valuation Output'!C40 -> 1077.984
C12: 0.11 | D12: =(('Valuation Output'!D25/(1+$C12)^1+'Valuation Output'!E25/(1+$C12)^2+'Valuation Output'!F25/(1+$C12)^3+'Valuation Output'!G25/(1+$C12)^4+'Valuation Output'!H25/(1+$C12)^5+('Valuation Output'!H25*(1+D$7)/($C12-D$7))/(1+$C12)^5)-'Valuation Output'!C37-'Valuation Output'!C38)/'Valuation Output'!C40 -> 744.45693 | E12: =(('Valuation Output'!D25/(1+$C12)^1+'Valuation Output'!E25/(1+$C12)^2+'Valuation Output'!F25/(1+$C12)^3+'Valuation Output'!G25/(1+$C12)^4+'Valuation Output'!H25/(1+$C12)^5+('Valuation Output'!H25*(1+E$7)/($C12-E$7))/(1+$C12)^5)-'Valuation Output'!C37-'Valuation Output'!C38)/'Valuation Output'!C40 -> 788.17525 | F12: =(('Valuation Output'!D25/(1+$C12)^1+'Valuation Output'!E25/(1+$C12)^2+'Valuation Output'!F25/(1+$C12)^3+'Valuation Output'!G25/(1+$C12)^4+'Valuation Output'!H25/(1+$C12)^5+('Valuation Output'!H25*(1+F$7)/($C12-F$7))/(1+$C12)^5)-'Valuation Output'!C37-'Valuation Output'!C38)/'Valuation Output'!C40 -> 839.17997 | G12: =(('Valuation Output'!D25/(1+$C12)^1+'Valuation Output'!E25/(1+$C12)^2+'Valuation Output'!F25/(1+$C12)^3+'Valuation Output'!G25/(1+$C12)^4+'Valuation Output'!H25/(1+$C12)^5+('Valuation Output'!H25*(1+G$7)/($C12-G$7))/(1+$C12)^5)-'Valuation Output'!C37-'Valuation Output'!C38)/'Valuation Output'!C40 -> 899.45826 | H12: =(('Valuation Output'!D25/(1+$C12)^1+'Valuation Output'!E25/(1+$C12)^2+'Valuation Output'!F25/(1+$C12)^3+'Valuation Output'!G25/(1+$C12)^4+'Valuation Output'!H25/(1+$C12)^5+('Valuation Output'!H25*(1+H$7)/($C12-H$7))/(1+$C12)^5)-'Valuation Output'!C37-'Valuation Output'!C38)/'Valuation Output'!C40 -> 971.79222
B15: BEAR / BASE / BULL
B16: Scenario | C16: UFCF multiplier | D16: WACC | E16: Terminal growth | F16: Enterprise value | G16: Equity value | H16: Value / share
B17: Bear | C17: 0.85 | D17: 0.11 | E17: 0.045 | F17: =('Valuation Output'!D25*$C17/(1+$D17)^1+'Valuation Output'!E25*$C17/(1+$D17)^2+'Valuation Output'!F25*$C17/(1+$D17)^3+'Valuation Output'!G25*$C17/(1+$D17)^4+'Valuation Output'!H25*$C17/(1+$D17)^5+('Valuation Output'!H25*$C17*(1+$E17)/($D17-$E17))/(1+$D17)^5) -> 61892.393 | G17: =F17-'Valuation Output'!C37-'Valuation Output'!C38 -> 64679.583 | H17: =G17/'Valuation Output'!C40 -> 674.30758
B18: Base | C18: 1 | D18: 0.1 | E18: 0.05 | F18: =('Valuation Output'!D25*$C18/(1+$D18)^1+'Valuation Output'!E25*$C18/(1+$D18)^2+'Valuation Output'!F25*$C18/(1+$D18)^3+'Valuation Output'!G25*$C18/(1+$D18)^4+'Valuation Output'!H25*$C18/(1+$D18)^5+('Valuation Output'!H25*$C18*(1+$E18)/($D18-$E18))/(1+$D18)^5) -> 93564.427 | G18: =F18-'Valuation Output'!C37-'Valuation Output'!C38 -> 96351.617 | H18: =G18/'Valuation Output'!C40 -> 1004.4998
B19: Bull | C19: 1.15 | D19: 0.09 | E19: 0.055 | F19: =('Valuation Output'!D25*$C19/(1+$D19)^1+'Valuation Output'!E25*$C19/(1+$D19)^2+'Valuation Output'!F25*$C19/(1+$D19)^3+'Valuation Output'!G25*$C19/(1+$D19)^4+'Valuation Output'!H25*$C19/(1+$D19)^5+('Valuation Output'!H25*$C19*(1+$E19)/($D19-$E19))/(1+$D19)^5) -> 151824.33 | G19: =F19-'Valuation Output'!C37-'Valuation Output'!C38 -> 154611.52 | H19: =G19/'Valuation Output'!C40 -> 1611.8799

Sheet Cover
B2: ASIAN PAINTS — EQUITY RESEARCH MODEL
B3: Consolidated 3-statement forecast and DCF valuation | Valuation date: 31 March 2026 | ₹ Crores unless stated
B5: KEY OUTPUTS
B6: Implied value / share | C6: ='Valuation Output'!C41 -> 1012.0479
B7: Enterprise value | C7: ='Valuation Output'!C34 -> 94288.447
B8: Equity value | C8: ='Valuation Output'!C39 -> 97075.637
B9: WACC | C9: ='Valuation Output'!C13 -> 0.0996225
B10: Terminal growth | C10: ='Valuation Output'!F6 -> 0.05
B12: FORECAST SNAPSHOT
B13: Metric | C13: FY26A | D13: FY27E | E13: FY28E | F13: FY29E | G13: FY30E | H13: FY31E
B14: Revenue | C14: ='Financial Model'!C5 -> 35583.54 | D14: ='Financial Model'!D5 -> 38963.976 | E14: ='Financial Model'!E5 -> 42665.554 | F14: ='Financial Model'!F5 -> 46505.454 | G14: ='Financial Model'!G5 -> 50458.417 | H14: ='Financial Model'!H5 -> 54495.091
B15: EBITDA | C15: ='Financial Model'!C15 -> 7419.72 | D15: ='Financial Model'!D15 -> 7942.9926 | E15: ='Financial Model'!E15 -> 8724.1355 | F15: ='Financial Model'!F15 -> 9592.8983 | G15: ='Financial Model'!G15 -> 10607.606 | H15: ='Financial Model'!H15 -> 11406.281
B16: PAT | C16: ='Financial Model'!C26 -> 4394.69 | D16: ='Financial Model'!D26 -> 5005.9841 | E16: ='Financial Model'!E26 -> 5502.959 | F16: ='Financial Model'!F26 -> 6061.19 | G16: ='Financial Model'!G26 -> 6724.4923 | H16: ='Financial Model'!H26 -> 7225.7616
B17: Unlevered FCF | C17: ='Valuation Output'!C25 -> 3863.3241 | D17: ='Valuation Output'!D25 -> 3904.8212 | E17: ='Valuation Output'!E25 -> 4341.1861 | F17: ='Valuation Output'!F25 -> 4807.9345 | G17: ='Valuation Output'!G25 -> 5388.1375 | H17: ='Valuation Output'!H25 -> 5793.033
B19: HOW TO USE THIS MODEL
B20: 1. Review blue assumptions in Assumptions and Drivers and Valuation Output.
B21: 2. Use Supporting Schedules to understand PPE, working capital, debt and leases.
B22: 3. Review the DCF bridge and WACC/g sensitivity before discussing the implied value.
B23: 4. Use Sensitivity & Scenarios to frame downside, base and upside cases.
B24: 5. Do not present the model until Checks shows MODEL OK and all sources/rationales are current.

Sheet Investment Thesis
B2: ASIAN PAINTS — INVESTMENT THESIS
B3: Cautiously constructive recovery case | FY26 actual base | FY27–FY31 forecast | Educational portfolio research
B5: THESIS IN ONE PARAGRAPH
B6: Asian Paints remains India’s leading paint and décor platform, supported by brand strength, manufacturing scale, product breadth and an expanding services ecosystem. The model assumes that FY25–FY26 weakness gives way to an 8.0%–9.5% revenue recovery while EBIT margins remain broadly stable. This outcome is plausible if decorative demand improves and the company protects channel relevance, but it is not assured: Birla Opus has materially expanded organised-industry capacity and distribution, increasing the risk of price, dealer-incentive and market-share pressure. The thesis is therefore a recovery case with meaningful competitive risk—not an unconditional recommendation.
B10: MODEL-LINKED INVESTMENT PILLARS
B11: 1 | C11: Franchise and distribution resilience | D11: Asian Paints reports leadership in Indian paints, 2.29 million KL annual domestic decorative capacity, a broad product portfolio and a large painting-services ecosystem. These capabilities support—but do not guarantee—the modeled recovery in revenue growth.
B12: 2 | C12: Margin and cash-generation capacity | D12: FY26 company disclosures show revenue from products and services up 4.3%, EBITDA up 12.4% and free cash flow up 110.4%. Backward integration, mix management and operating discipline provide a basis for the model’s broadly stable 17.4%–17.9% EBIT margin.
B13: 3 | C13: Adjacency and services optionality | D13: Waterproofing, B2B coatings, home décor and professional services broaden the customer relationship beyond paint. The model does not assign a separate option value, making successful scaling a potential upside driver rather than an embedded valuation assumption.
B15: WHAT MUST GO RIGHT IN THE BASE CASE
B16: Model assumption | C16: FY27–FY31 expectation | D16: Required business evidence | E16: Assessment
B17: Revenue growth | C17: 9.5% declining to 8.0% | D17: Decorative volumes and price/mix recover despite stronger competition | E17: Most demanding assumption; recent history was materially weaker
B18: EBIT margin | C18: 17.4%–17.9% | D18: Input-cost control and operating leverage offset promotional intensity | E18: Reasonable but vulnerable to price competition and adverse mix
B19: Capex | C19: 5.0% of revenue | D19: Investment supports capacity/efficiency without depressing cash conversion | E19: Conservative cash-investment assumption relative to a low-capex recovery
B20: Working capital | C20: 105 / 46 / 71 days | D20: Inventory, receivables and payables remain controlled during recovery | E20: Requires execution discipline; monitored through the model’s NWC schedule
B22: KEY RISKS AND DISCONFIRMING EVIDENCE
B23: Risk | C23: Why it matters | D23: Model signal
B24: Competitive intensity | C24: Birla Opus has installed 1,332 MLPA of capacity, described as roughly 24% of organised-industry capacity, and expanded across 8,000+ towns. | D24: Revenue growth and gross margin fall below the bear-case trajectory
B25: Demand and downtrading | C25: Asian Paints cited muted demand, adverse mix and downtrading in FY25; continued weakness would invalidate the modeled growth recovery. | D25: Volumes fail to recover, premium mix weakens or dealer incentives rise
B26: Raw materials and pricing | C26: Paint is raw-material intensive. Crude-linked input inflation or price reductions can compress gross margin and cash flow. | D26: Gross margin fails to hold near 43% and UFCF conversion deteriorates
B28: CATALYSTS AND VALUATION
B29: Potential catalyst | C29: Evidence to watch | D29: Valuation implication | E29: Scenario | F29: UFCF / WACC / g | G29: Implied value / share | H29: Interpretation
B30: Decorative-demand recovery | C30: Sustained volume growth and improving price/mix | D30: Supports base-case revenue growth | E30: Bear | F30: 0.85x / 11.0% / 4.5% | G30: ='Sensitivity & Scenarios'!H17 -> 674.30758 | H30: Prolonged demand and competitive pressure
B31: Margin resilience | C31: Stable gross margin and improving EBITDA conversion | D31: Protects UFCF and terminal value | E31: Base | F31: 1.00x / 10.0% / 5.0% | G31: ='Sensitivity & Scenarios'!H18 -> 1004.4998 | H31: Recovery with broadly stable margins
B32: Services/B2B scale | C32: Higher contribution from waterproofing, projects and services | D32: Potential upside not separately valued | E32: Bull | F32: 1.15x / 9.0% / 5.5% | G32: ='Sensitivity & Scenarios'!H19 -> 1611.8799 | H32: Stronger growth, mix and cash conversion
B33: Competitive moderation | C33: Lower promotional intensity and stable channel economics | D33: Reduces bear-case probability | E33: Primary DCF | F33: Calculated WACC / 5.0% | G33: ='Valuation Output'!C41 -> 1012.0479 | H33: Main model output using 9.96% WACC
B35: SOURCES AND CONCLUSION
B36: Source | C36: URL | D36: Portfolio conclusion
B37: Asian Paints FY26 Annual Report | C37: https://www.asianpaints.com/content/annualreport/annual-report-25-26.html | D37: The operating franchise remains high quality, but the model’s valuation depends heavily on a revenue recovery that must be demonstrated against a more competitive industry structure.
B38: Asian Paints FY25 Q4 Press Release | C38: https://www.asianpaints.com/content/dam/asianpaints/website/secondary-navigation/press-releases/2024-2025/Press_Release_Q4_FY25.pdf | D38: The thesis would strengthen if volume growth, price/mix and margins improve simultaneously without a material working-capital build.
B39: Asian Paints Investor Centre | C39: https://www.asianpaints.com/more/investors.html | D39: The thesis would weaken if competition forces structurally lower pricing, dealer economics or margins.
B40: Grasim / Birla Opus Q1 FY26 update | C40: https://www.grasim.com/media/press-releases/q1fy2026-creating-scaling-growth-engines-for-viksit-bharat | D40: Educational research only — not investment advice or a buy/sell recommendation.
